2022-01-18 11:20:24,909 INFO    MainThread:18141 [wandb_setup.py:_flush():71] setting env: {}
2022-01-18 11:20:24,909 INFO    MainThread:18141 [wandb_setup.py:_flush():71] setting login settings: {}
2022-01-18 11:20:24,909 INFO    MainThread:18141 [wandb_init.py:_log_setup():371] Logging user logs to /Users/laurengreenspan/GitDLs/TreeNiNNew/code_ginkgo/recnn/wandb/run-20220118_112024-x52gnq7o/logs/debug.log
2022-01-18 11:20:24,909 INFO    MainThread:18141 [wandb_init.py:_log_setup():372] Logging internal logs to /Users/laurengreenspan/GitDLs/TreeNiNNew/code_ginkgo/recnn/wandb/run-20220118_112024-x52gnq7o/logs/debug-internal.log
2022-01-18 11:20:24,909 INFO    MainThread:18141 [wandb_init.py:init():404] calling init triggers
2022-01-18 11:20:24,909 INFO    MainThread:18141 [wandb_init.py:init():409] wandb.init called with sweep_config: {}
config: {}
2022-01-18 11:20:24,910 INFO    MainThread:18141 [wandb_init.py:init():460] starting backend
2022-01-18 11:20:24,910 INFO    MainThread:18141 [backend.py:_multiprocessing_setup():99] multiprocessing start_methods=spawn,fork,forkserver, using: spawn
2022-01-18 11:20:24,914 INFO    MainThread:18141 [backend.py:ensure_launched():216] starting backend process...
2022-01-18 11:20:24,935 ERROR   MainThread:18141 [wandb_init.py:init():958] error
Traceback (most recent call last):
  File "/Users/laurengreenspan/miniconda3/lib/python3.8/site-packages/wandb/sdk/wandb_init.py", line 931, in init
    run = wi.init()
  File "/Users/laurengreenspan/miniconda3/lib/python3.8/site-packages/wandb/sdk/wandb_init.py", line 467, in init
    backend.ensure_launched()
  File "/Users/laurengreenspan/miniconda3/lib/python3.8/site-packages/wandb/sdk/backend/backend.py", line 219, in ensure_launched
    self.wandb_process.start()
  File "/Users/laurengreenspan/miniconda3/lib/python3.8/multiprocessing/process.py", line 121, in start
    self._popen = self._Popen(self)
  File "/Users/laurengreenspan/miniconda3/lib/python3.8/multiprocessing/context.py", line 284, in _Popen
    return Popen(process_obj)
  File "/Users/laurengreenspan/miniconda3/lib/python3.8/multiprocessing/popen_spawn_posix.py", line 32, in __init__
    super().__init__(process_obj)
  File "/Users/laurengreenspan/miniconda3/lib/python3.8/multiprocessing/popen_fork.py", line 19, in __init__
    self._launch(process_obj)
  File "/Users/laurengreenspan/miniconda3/lib/python3.8/multiprocessing/popen_spawn_posix.py", line 42, in _launch
    prep_data = spawn.get_preparation_data(process_obj._name)
  File "/Users/laurengreenspan/miniconda3/lib/python3.8/multiprocessing/spawn.py", line 154, in get_preparation_data
    _check_not_importing_main()
  File "/Users/laurengreenspan/miniconda3/lib/python3.8/multiprocessing/spawn.py", line 134, in _check_not_importing_main
    raise RuntimeError('''
RuntimeError: 
        An attempt has been made to start a new process before the
        current process has finished its bootstrapping phase.

        This probably means that you are not using fork to start your
        child processes and you have forgotten to use the proper idiom
        in the main module:

            if __name__ == '__main__':
                freeze_support()
                ...

        The "freeze_support()" line can be omitted if the program
        is not going to be frozen to produce an executable.
